<?xml version="1.0" ?>
<robot name="fr3">
    <material name="Silver">
        <color rgba="1.0 1.0 1.0 1.0" />
    </material>
    <material name="Black">
        <color rgba="0.0 0.0 0.0 1.0" />
    </material>
    <material name="Chrome">
        <color rgba="0.0 0.0 0.0 1.0" />
    </material>
    <material name="DarkGrey">
        <color rgba="0.33 0.33 0.33 1.0" />
    </material>
    <material name="Grey">
        <color rgba="0.55 0.55 0.55 0.8" />
    </material>
    <material name="OpaqueGreen">
        <color rgba="0.0 1.0 0.0 0.2" />
    </material>
    <material name="OpaqueRed">
        <color rgba="1.0 0.0 0.0 0.2" />
    </material>

    <link name="link0">
      <inertial>
        <mass value="2.3966"/>
        <origin rpy="0 0 0" xyz="-0.0172 0.0004 0.0745"/>
        <inertia ixx="0.0090" ixy="0.0000" ixz="0.0020" iyy="0.0115" iyz="0.0000" izz="0.0085"/>
      </inertial>
      <visual>
        <geometry>
          <mesh filename="meshes/visual/link0.dae" />
        </geometry>
      </visual>
      <collision>
        <geometry>
          <mesh filename="meshes/collision/link0.obj" scale="1.0 1.0 1.0"/>
        </geometry>
      </collision>
    </link>
    
    <joint name="joint1" type="revolute">
      <origin rpy="-7.070853699609467e-20 7.01457620144154e-17 -5.871445110820177e-17" xyz="1.6453621370977905e-17 8.128699592849844e-17 0.3330000000000001" />
      <parent link="link0" />
      <child link="link1" />
      <axis xyz="0 0 1" />
      <limit effort="87" lower="-2.3093" upper="2.3093" velocity="2.0"/>
    </joint>
    
    <link name="link1">
      <inertial>
        <mass value="2.893803062486869"/>
        <origin rpy="0 0 0" xyz="-2.4735319556366423e-06 -0.017250815975158318 -0.03815013033428774"/>
        <inertia ixx="0.023694811184667954" ixy="1.229000138197895e-05" ixz="-0.0001108593539413164" iyy="0.02236098042097353" iyz="-0.0018998374804063082" izz="0.006088231578292325"/>
      </inertial>
      <visual>
        <geometry>
          <mesh filename="meshes/visual/link1.dae" />
        </geometry>
      </visual>
      <collision>
        <geometry>
          <mesh filename="meshes/collision/link1.obj" scale="1.0 1.0 1.0"/>
        </geometry>
      </collision>
    </link>
    
    <joint name="joint2" type="revolute">
      <origin rpy="-1.569663240507509 2.1599930128152177e-05 -1.8298134019183714e-12" xyz="-0.00022476212368955053 0.000203106104820772 2.8230196526247564e-17" />
      <parent link="link1" />
      <child link="link2" />
      <axis xyz="0 0 1" />
      <limit effort="87.0" lower="-1.5133" upper="1.5133" velocity="1.0" />
    </joint>
    
    <link name="link2">
      <inertial>
        <mass value="3.592878787527304"/>
        <origin rpy="0 0 0" xyz="0.002005970330965363 -0.08712765724482352 0.007180352038888694"/>
        <inertia ixx="0.039563995426127055" ixy="0.0033018498587016887" ixz="0.0034504193180185214" iyy="0.020106484463390792" iyz="-0.004593801471807505" izz="0.054506273232226184"/>
      </inertial>
      <visual>
        <geometry>
          <mesh filename="meshes/visual/link2.dae" />
        </geometry>
      </visual>
      <collision>
        <geometry>
          <mesh filename="meshes/collision/link2.obj" scale="1.0 1.0 1.0"/>
        </geometry>
      </collision>
    </link>
    
    <joint name="joint3" type="revolute">
      <origin rpy="1.5699746877243725 -0.0010472273004368765 1.3751793428407215e-05" xyz="2.483591980168594e-05 -0.31585675510886724 0.00020310596611635017" />
      <parent link="link2" />
      <child link="link3" />
      <axis xyz="0 0 1" />
      <limit effort="87.0" lower="-2.4937" upper="2.4937" velocity="1.5" />
    </joint>
    
    <link name="link3">
      <inertial>
        <mass value="2.7569651160314086"/>
        <origin rpy="0 0 0" xyz="0.03619671048933047 -0.01920086789719376 -0.033459938809657634"/>
        <inertia ixx="0.021140735319055474" ixy="0.0014004906920248238" ixz="-0.003287061866154945" iyy="0.018952330296571996" iyz="-0.0014560443467341638" izz="0.015344984013831355"/>
      </inertial>
      <visual>
        <geometry>
          <mesh filename="meshes/visual/link3.dae" />
        </geometry>
      </visual>
      <collision>
        <geometry>
          <mesh filename="meshes/collision/link3.obj" scale="1.0 1.0 1.0"/>
        </geometry>
      </collision>
    </link>
    
    <joint name="joint4" type="revolute">
      <origin rpy="1.5689175804611115 0.0007229190055229249 0.0010286904104520262" xyz="0.08238210033982035 0.000224830817889553 -0.00014307764469451107" />
      <parent link="link3" />
      <child link="link4" />
      <axis xyz="0 0 1" />
      <limit effort="87.0" lower="-2.7478" upper="-0.4461" velocity="1.25" />
    </joint>
    
    <link name="link4">
      <inertial>
        <mass value="1.700671459658142"/>
        <origin rpy="0 0 0" xyz="-0.02062503517503538 0.05183635205323422 -0.021881299829643604"/>
        <inertia ixx="0.0325795542881433" ixy="0.014152048725010413" ixz="0.00743052736898332" iyy="0.024002583248684012" iyz="-0.0010434011633429687" izz="0.04045612015550877"/>
      </inertial>
      <visual>
        <geometry>
          <mesh filename="meshes/visual/link4.dae" />
        </geometry>
      </visual>
      <collision>
        <geometry>
          <mesh filename="meshes/collision/link4.obj" scale="1.0 1.0 1.0"/>
        </geometry>
      </collision>
    </link>
    
    <joint name="joint5" type="revolute">
        <origin rpy="-1.5725568343411012 0.002818808125247204 -0.0008331711560464819" xyz="-0.08277427447127986 0.38391682272804906 -0.0002252205503509532" />
        <parent link="link4" />
        <child link="link5" />
        <axis xyz="0 0 1" />
        <limit effort="12.0" lower="-2.48" upper="2.48" velocity="3.0" />
    </joint>
    
    <link name="link5">
      <inertial>
        <mass value="2.7061124194103123"/>
        <origin rpy="0 0 0" xyz="0.008174917788578265 0.0343743840146984 -0.0813540395423721"/>
        <inertia ixx="0.03433664366225801" ixy="-0.00443989032775479" ixz="-0.0014545036110982523" iyy="0.03120727747187554" iyz="0.007766956034105186" izz="0.012158380449686555"/>
      </inertial>
      <visual>
        <geometry>
          <mesh filename="meshes/visual/link5.dae" />
        </geometry>
      </visual>
      <collision>
        <geometry>
          <mesh filename="meshes/collision/link5.obj" scale="1.0 1.0 1.0"/>
        </geometry>
      </collision>
    </link>
    
    <joint name="joint6" type="revolute">
      <origin rpy="1.5664543458823141 0.0005001399131159785 0.002820279303635351" xyz="0.0007331599331725679 0.0002672518669462526 -8.300776996215768e-05" />
      <parent link="link5" />
      <child link="link6" />
      <axis xyz="0 0 1" />
      <limit effort="12.0" lower="0.8521" upper="4.2094" velocity="1.5" />
    </joint>
    
    <link name="link6">
      <inertial>
        <mass value="1.667489814891974"/>
        <origin rpy="0 0 0" xyz="0.043313788446360565 -0.031896785492225285 -0.007884631737613883"/>
        <inertia ixx="0.0040159628495273015" ixy="0.003939000483595309" ixz="0.0007572054689726043" iyy="0.009714140685447209" iyz="-0.0009308930133401629" izz="0.010680610301928933"/>
      </inertial>
      <visual>
        <geometry>
          <mesh filename="meshes/visual/link6.dae" />
        </geometry>
      </visual>
      <collision>
        <geometry>
          <mesh filename="meshes/collision/link6.obj" scale="1.0 1.0 1.0"/>
        </geometry>
      </collision>
    </link>
    
    <joint name="joint7" type="revolute">
      <origin rpy="1.5708749860536488 2.9911583861364804e-08 -0.0003802655003243309" xyz="0.08680641996738661 -0.0012231086910573829 -0.00026553941424996123" />
      <parent link="link6" />
      <child link="link7" />
      <axis xyz="0 0 1" />
      <limit effort="12.0" lower="-2.6895" upper="2.6895" velocity="3.0" />
    </joint>
    
    <link name="link7">
      <inertial>
        <mass value="0.6903970798841693"/>
        <origin rpy="0 0 0" xyz="0.004629204923829346 0.0088368321403912 -0.016556813575856092"/>
        <inertia ixx="0.00021085653316374654" ixy="-2.4172924068885584e-05" ixz="4.531305073474598e-05" iyy="0.00017721557382604255" iyz="8.673435532207295e-05" izz="6.089851503223665e-05"/>
      </inertial>    
      <visual>
        <geometry>
          <mesh filename="meshes/visual/link7.dae" />
        </geometry>
      </visual>
      <collision>
        <geometry>
          <mesh filename="meshes/collision/link7.obj" scale="1.0 1.0 1.0"/>
        </geometry>
      </collision>
    </link>
      
    <joint name="joint8" type="fixed">
      <origin rpy="0 0 0" xyz="0 0 0.107"/>
      <parent link="link7"/>
      <child link="link8"/>
      <axis xyz="0 0 1"/>
    </joint>

    <link name="link8">
      <inertial>
        <origin rpy="0 0 0" xyz="0 0 0"/>
        <mass value="0.0"/>
        <inertia ixx="0.1" ixy="0" ixz="0" iyy="0.1" iyz="0" izz="0.1"/>
      </inertial>
    </link>

</robot>
